Workbook

Sheet 分析表
B1: 一、初步的分类
B2: 级别 | C2: 职级 | D2: 年限 | E2: 岗位名称 | F2: 在招岗位数量 | G2: 收入区间 | H2: 最高薪资 | I2: 最低薪资 | J2: 平均数 | K2: 中位值
B3: 初级 | C3: 1 | D3: 1-3年 | E3: 销售岗 | F3: 23 | G3: 10-20k | H3: 24 | I3: 8 | J3: 14.021739 | K3: 14
B4: 中级 | C4: 2 | D4: 1-3年、3-5年 | E4: 销售经理 | F4: 70 | G4: 15-40k | H4: 60 | I4: 8 | J4: 21.321429 | K4: 19.25
B5: 高级 | C5: 3 | D5: 3-5年、5-10年 | E5: 高级销售经理 | F5: 40 | G5: 15-50k | H5: 65 | I5: 10 | J5: 27.5625 | K5: 22.5
B6: 资深 | C6: 4 | D6: 5-10年 | E6: 销售专家 | F6: 8 | G6: 30-60k | H6: 65 | I6: 26 | J6: 44.75 | K6: 45
B7: 管理人员 | C7: 5 | E7: 销售经理/总监 | F7: 12 | G7: 15-40k | H7: 65 | I7: 13 | J7: 25.791667 | K7: 22.5
B10: 二、市场薪酬水平
B11: 1、计算每个职级的分位值：例如中位数（50分位）、以此类推 | G11: 参考函数：PERCENTILE
B12: 职级 | C12: 市场10分位 | D12: 市场25分位 | E12: 市场50分位 | F12: 市场75分位 | G12: 市场90分位 | I12: 例如：年薪12万处于什么分位？
B13: 1 | C13: =PERCENTILE(Sheet2!$D2:$D24,0.1) -> 12.5 | D13: =PERCENTILE(Sheet2!$D2:$D24,0.25) -> 12.5 | E13: =PERCENTILE(Sheet2!$D2:$D24,0.5) -> 14 | F13: =PERCENTILE(Sheet2!$D2:$D24,0.75) -> 15.25 | G13: =PERCENTILE(Sheet2!$D2:$D24,0.9) -> 15.9
B14: 2 | C14: =PERCENTILE(Sheet2!$H2:$H71,0.1) -> 15.5 | D14: =PERCENTILE(Sheet2!$H2:$H71,0.25) -> 17.5 | E14: =PERCENTILE(Sheet2!$H2:$H71,0.5) -> 19.25 | F14: =PERCENTILE(Sheet2!$H2:$H71,0.75) -> 22.5 | G14: =PERCENTILE(Sheet2!$H2:$H71,0.9) -> 31.4
B15: 3 | C15: =PERCENTILE(Sheet2!$L2:$L41,0.1) -> 15.5 | D15: =PERCENTILE(Sheet2!$L2:$L41,0.25) -> 16 | E15: =PERCENTILE(Sheet2!$L2:$L41,0.5) -> 22.5 | F15: =PERCENTILE(Sheet2!$L2:$L41,0.75) -> 40 | G15: =PERCENTILE(Sheet2!$L2:$L41,0.9) -> 45
B16: 4 | C16: =PERCENTILE(Sheet2!$P2:$P9,0.1) -> 42.9 | D16: =PERCENTILE(Sheet2!$P2:$P9,0.25) -> 45 | E16: =PERCENTILE(Sheet2!$P2:$P9,0.5) -> 45 | F16: =PERCENTILE(Sheet2!$P2:$P9,0.75) -> 45 | G16: =PERCENTILE(Sheet2!$P2:$P9,0.9) -> 46.5
B17: 5 | C17: =PERCENTILE(Sheet2!$T2:$T13,0.1) -> 20 | D17: =PERCENTILE(Sheet2!$T2:$T13,0.25) -> 21.875 | E17: =PERCENTILE(Sheet2!$T2:$T13,0.5) -> 22.5 | F17: =PERCENTILE(Sheet2!$T2:$T13,0.75) -> 28.125 | G17: =PERCENTILE(Sheet2!$T2:$T13,0.9) -> 30
B19: 2、计算每个职级的薪酬水平 | G19: 参考函数：LN函数取对数
B20: 职级 | C20: 市场10分位 | D20: 市场25分位 | E20: 市场50分位 | F20: 市场75分位 | G20: 市场90分位 | I20: 目的：薪酬统一到正态分布的水平
B21: 1 | C21: =LN(C13) -> 2.5257286 | D21: =LN(D13) -> 2.5257286 | E21: =LN(E13) -> 2.6390573 | F21: =LN(F13) -> 2.7245795 | G21: =LN(G13) -> 2.7663191
B22: 2 | C22: =LN(C14) -> 2.74084 | D22: =LN(D14) -> 2.8622009 | E22: =LN(E14) -> 2.9575111 | F22: =LN(F14) -> 3.1135153 | G22: =LN(G14) -> 3.4468079
B23: 3 | C23: =LN(C15) -> 2.74084 | D23: =LN(D15) -> 2.7725887 | E23: =LN(E15) -> 3.1135153 | F23: =LN(F15) -> 3.6888795 | G23: =LN(G15) -> 3.8066625
B24: 4 | C24: =LN(C16) -> 3.7588718 | D24: =LN(D16) -> 3.8066625 | E24: =LN(E16) -> 3.8066625 | F24: =LN(F16) -> 3.8066625 | G24: =LN(G16) -> 3.8394523
B25: 5 | C25: =LN(C17) -> 2.9957323 | D25: =LN(D17) -> 3.0853444 | E25: =LN(E17) -> 3.1135153 | F25: =LN(F17) -> 3.3366589 | G25: =LN(G17) -> 3.4011974
B27: 3、求出斜率和截距对数，得到回归后的市场薪酬水平 | G27: 斜率参考函数：SLOPE函数；截距参考函数：INTERCEPT函数
B28: 数据 | C28: 市场10分位 | D28: 市场25分位 | E28: 市场50分位 | F28: 市场75分位 | G28: 市场90分位
B29: 斜率 | C29: {=SLOPE(C21:C25,$B21:$B25)} -> 0.19580391 | D29: {=SLOPE(D21:D25,$B21:$B25)} -> 0.20636932 | E29: {=SLOPE(E21:E25,$B21:$B25)} -> 0.17980674 | F29: {=SLOPE(F21:F25,$B21:$B25)} -> 0.19173059 | G29: {=SLOPE(G21:G25,$B21:$B25)} -> 0.1662401
B30: 截距对数 | C30: {=INTERCEPT(C21:C25,$B21:$B25)} -> 2.3649908 | D30: {=INTERCEPT(D21:D25,$B21:$B25)} -> 2.3913971 | E30: {=INTERCEPT(E21:E25,$B21:$B25)} -> 2.5866321 | F30: {=INTERCEPT(F21:F25,$B21:$B25)} -> 2.7588674 | G30: {=INTERCEPT(G21:G25,$B21:$B25)} -> 2.9533675
B33: 4、计算回归后的市场薪酬水平 | G33: 参考函数：计算结果=exp(截距对数)*exp(斜率*职级)
B34: 职级 | C34: 市场10分位 | D34: 市场25分位 | E34: 市场50分位 | F34: 市场75分位 | G34: 市场90分位
B35: 1 | C35: =EXP(C30+C29*$B35) -> 12.946102 | D35: =EXP(D30+D29*$B35) -> 13.433699 | E35: =EXP(E30+E29*$B35) -> 15.901904 | F35: =EXP(F30+F29*$B35) -> 19.117381 | G35: =EXP(G30+G29*$B35) -> 22.637496
B36: 2 | C36: =EXP(C30+C29*$B36) -> 15.746193 | D36: =EXP(D30+D29*$B36) -> 16.512798 | E36: =EXP(E30+E29*$B36) -> 19.034356 | F36: =EXP(F30+F29*$B36) -> 23.157728 | G36: =EXP(G30+G29*$B36) -> 26.731636
B37: 3 | C37: =EXP(C30+C29*$B37) -> 19.151912 | D37: =EXP(D30+D29*$B37) -> 20.297648 | E37: =EXP(E30+E29*$B37) -> 22.783858 | F37: =EXP(F30+F29*$B37) -> 28.051977 | G37: =EXP(G30+G29*$B37) -> 31.566229
B38: 4 | C38: =EXP(C30+C29*$B38) -> 23.294248 | D38: =EXP(D30+D29*$B38) -> 24.950013 | E38: =EXP(E30+E29*$B38) -> 27.271959 | F38: =EXP(F30+F29*$B38) -> 33.980598 | G38: =EXP(G30+G29*$B38) -> 37.275189
B39: 5 | C39: =EXP(C30+C29*$B39) -> 28.332523 | D39: =EXP(D30+D29*$B39) -> 30.668733 | E39: =EXP(E30+E29*$B39) -> 32.644154 | F39: =EXP(F30+F29*$B39) -> 41.162198 | G39: =EXP(G30+G29*$B39) -> 44.016653
B42: 5、年薪
B43: 职级 | C43: 市场10分位 | D43: 市场25分位 | E43: 市场50分位 | F43: 市场75分位 | G43: 市场90分位
B44: 1 | C44: =C35*1.2 -> 15.535323 | D44: =D35*1.2 -> 16.120439 | E44: =E35*1.2 -> 19.082284 | F44: =F35*1.2 -> 22.940858 | G44: =G35*1.2 -> 27.164995
B45: 2 | C45: =C36*1.2 -> 18.895432 | D45: =D36*1.2 -> 19.815358 | E45: =E36*1.2 -> 22.841227 | F45: =F36*1.2 -> 27.789273 | G45: =G36*1.2 -> 32.077963
B46: 3 | C46: =C37*1.2 -> 22.982294 | D46: =D37*1.2 -> 24.357178 | E46: =E37*1.2 -> 27.34063 | F46: =F37*1.2 -> 33.662373 | G46: =G37*1.2 -> 37.879474
B47: 4 | C47: =C38*1.2 -> 27.953098 | D47: =D38*1.2 -> 29.940016 | E47: =E38*1.2 -> 32.726351 | F47: =F38*1.2 -> 40.776718 | G47: =G38*1.2 -> 44.730227
B48: 5 | C48: =C39*1.2 -> 33.999028 | D48: =D39*1.2 -> 36.80248 | E48: =E39*1.2 -> 39.172984 | F48: =F39*1.2 -> 49.394637 | G48: =G39*1.2 -> 52.819983

Sheet 数据清洗结果
A1: 明细表进行归类
A2: 外部信息
A3: 序号 | B3: 调研岗位 | C3: 调研公司 | D3: 级别 | E3: 职级 | F3: 岗位职责 | G3: 工作地点 | J3: 经验要求 | K3: 学历要求 | L3: 月度薪酬 | M3: 基本福利信息
G4: 省份 | H4: 城市 | I4: 区域
A5: 1 | B5: 销售岗 | C5: 电科金仓 | D5: {=_xlfn.IFS(J5="经验不限","初级",J5="1-3年","初级",J5="3-5年","中级",J5="5-10年","高级",J5="10年以上","资深")} -> 初级 | E5: {=_xlfn.IFS(D5="初级",1,D5="中级",2,D5="高级",3,D5="资深",4,D5="管理",5)} -> 1 | F5: 大区 | G5: 福州 | H5: 鼓楼区 | I5: 湖前 | J5: 经验不限 | K5: 本科 | L5: 10-11K | M5: 生日福利|定期体检|年终奖|餐补|股票期权|通讯补贴|带薪年假|交通补助|五险一金|绩效奖金|团建聚餐|零食下午茶|意外险|节日福利
A6: 2 | B6: 销售经理 | C6: 电科金仓 | D6: {=_xlfn.IFS(J6="经验不限","初级",J6="1-3年","初级",J6="3-5年","中级",J6="5-10年","高级",J6="10年以上","资深")} -> 中级 | E6: {=_xlfn.IFS(D6="初级",1,D6="中级",2,D6="高级",3,D6="资深",4,D6="管理",5)} -> 2 | F6: 区域行业|数据库 | G6: 南昌 | H6: 青山湖区 | I6: 京东 | J6: 3-5年 | K6: 本科 | L6: 11-22K | M6: 通讯补贴|交通补助|节日福利|年终奖|带薪年假|五险一金|绩效奖金|零食下午茶|生日福利|团建聚餐|意外险|定期体检|股票期权|餐补
A7: 3 | B7: 销售经理 | C7: 电科金仓 | D7: {=_xlfn.IFS(J7="经验不限","初级",J7="1-3年","初级",J7="3-5年","中级",J7="5-10年","高级",J7="10年以上","资深")} -> 中级 | E7: {=_xlfn.IFS(D7="初级",1,D7="中级",2,D7="高级",3,D7="资深",4,D7="管理",5)} -> 2 | F7: 拉萨|基础软件 | G7: 拉萨 | H7: 城关区 | I7: 市政府 | J7: 3-5年 | K7: 本科 | L7: 15-20K | M7: 节日福利|交通补助|带薪年假|五险一金|团建聚餐|意外险|通讯补贴|年终奖|定期体检|餐补|生日福利|零食下午茶|股票期权|绩效奖金
A8: 4 | B8: 销售经理 | C8: 电科金仓 | D8: {=_xlfn.IFS(J8="经验不限","初级",J8="1-3年","初级",J8="3-5年","中级",J8="5-10年","高级",J8="10年以上","资深")} -> 中级 | E8: {=_xlfn.IFS(D8="初级",1,D8="中级",2,D8="高级",3,D8="资深",4,D8="管理",5)} -> 2 | F8: 区域行业 | G8: 福州 | H8: 闽侯县 | I8: 新西客站 | J8: 3-5年 | K8: 本科 | L8: 12-24K | M8: 年终奖|生日福利|意外险|餐补|交通补助|节日福利|团建聚餐|带薪年假|定期体检|绩效奖金|通讯补贴|零食下午茶|股票期权|五险一金
A9: 6 | B9: 销售经理 | C9: 电科金仓 | D9: {=_xlfn.IFS(J9="经验不限","初级",J9="1-3年","初级",J9="3-5年","中级",J9="5-10年","高级",J9="10年以上","资深")} -> 中级 | E9: {=_xlfn.IFS(D9="初级",1,D9="中级",2,D9="高级",3,D9="资深",4,D9="管理",5)} -> 2 | F9: 区域行业 | G9: 杭州 | H9: 西湖区 | I9: 西溪 | J9: 3-5年 | K9: 本科 | L9: 15-30K | M9: 通讯补贴|零食下午茶|生日福利|餐补|年终奖|节日福利|团建聚餐|股票期权|绩效奖金|带薪年假|交通补助|定期体检|意外险|五险一金
A10: 7 | B10: 销售经理 | C10: 电科金仓 | D10: {=_xlfn.IFS(J10="经验不限","初级",J10="1-3年","初级",J10="3-5年","中级",J10="5-10年","高级",J10="10年以上","资深")} -> 中级 | E10: {=_xlfn.IFS(D10="初级",1,D10="中级",2,D10="高级",3,D10="资深",4,D10="管理",5)} -> 2 | F10: 生态 | G10: 北京 | H10: 朝阳区 | I10: 望京 | J10: 3-5年 | K10: 本科 | L10: 15-25K | M10: 生日福利|绩效奖金|交通补助|意外险|带薪年假|节日福利|餐补|五险一金|股票期权|年终奖|通讯补贴|零食下午茶|定期体检|团建聚餐
A11: 8 | B11: 销售经理/总监 | C11: 电科金仓 | D11: 管理 | E11: {=_xlfn.IFS(D11="初级",1,D11="中级",2,D11="高级",3,D11="资深",4,D11="管理",5)} -> 5 | F11: 交通行业 | G11: 广州 | H11: 越秀区 | I11: 北京路 | J11: 5-10年 | K11: 本科 | L11: 15-30K | M11: 通讯补贴|定期体检|股票期权|五险一金|团建聚餐|交通补助|餐补|带薪年假|年终奖|节日福利|绩效奖金|意外险|生日福利|零食下午茶
A12: 9 | B12: 销售经理 | C12: 电科金仓 | D12: {=_xlfn.IFS(J12="经验不限","初级",J12="1-3年","初级",J12="3-5年","中级",J12="5-10年","高级",J12="10年以上","资深")} -> 中级 | E12: {=_xlfn.IFS(D12="初级",1,D12="中级",2,D12="高级",3,D12="资深",4,D12="管理",5)} -> 2 | F12: 部委行业 | G12: 北京 | H12: 朝阳区 | I12: 望京 | J12: 3-5年 | K12: 本科 | L12: 15-30K | M12: 生日福利|年终奖|意外险|通讯补贴|零食下午茶|餐补|五险一金|股票期权|绩效奖金|交通补助|带薪年假|定期体检|团建聚餐|节日福利
A13: 10 | B13: 销售经理 | C13: 电科金仓 | D13: {=_xlfn.IFS(J13="经验不限","初级",J13="1-3年","初级",J13="3-5年","中级",J13="5-10年","高级",J13="10年以上","资深")} -> 中级 | E13: {=_xlfn.IFS(D13="初级",1,D13="中级",2,D13="高级",3,D13="资深",4,D13="管理",5)} -> 2 | F13: 区域行业 | G13: 宁波 | H13: 鄞州区 | I13: 福明 | J13: 3-5年 | K13: 本科 | L13: 15-25K | M13: 带薪年假|五险一金|意外险|定期体检|年终奖|餐补|绩效奖金|团建聚餐|通讯补贴|交通补助|零食下午茶|股票期权|节日福利|生日福利
A14: 11 | B14: 事业部总经理 | C14: 电科金仓 | D14: 管理 | E14: {=_xlfn.IFS(D14="初级",1,D14="中级",2,D14="高级",3,D14="资深",4,D14="管理",5)} -> 5 | F14: 企业|政府/社会团体|数据库|区域行业|事业部管理 | G14: 北京 | H14: 朝阳区 | I14: 望京 | J14: 10年以上 | K14: 本科 | L14: 35-65K | M14: 交通补助|节日福利|意外险|通讯补贴|团建聚餐|生日福利|年终奖|股票期权|定期体检|五险一金|绩效奖金|零食下午茶|餐补|带薪年假
A15: 12 | B15: 销售经理 | C15: 电科金仓 | D15: {=_xlfn.IFS(J15="经验不限","初级",J15="1-3年","初级",J15="3-5年","中级",J15="5-10年","高级",J15="10年以上","资深")} -> 中级 | E15: {=_xlfn.IFS(D15="初级",1,D15="中级",2,D15="高级",3,D15="资深",4,D15="管理",5)} -> 2 | F15: 区域行业 | G15: 太原 | H15: 小店区 | I15: 学府街 | J15: 3-5年 | K15: 本科 | L15: 12-24K | M15: 意外险|生日福利|节日福利|股票期权|零食下午茶|团建聚餐|通讯补贴|带薪年假|餐补|交通补助|定期体检|年终奖|绩效奖金|五险一金
A16: 13 | B16: 高级销售经理 | C16: 电科金仓 | D16: {=_xlfn.IFS(J16="经验不限","初级",J16="1-3年","初级",J16="3-5年","中级",J16="5-10年","高级",J16="10年以上","资深")} -> 高级 | E16: {=_xlfn.IFS(D16="初级",1,D16="中级",2,D16="高级",3,D16="资深",4,D16="管理",5)} -> 3 | F16: 区域行业 | G16: 广州 | H16: 越秀区 | I16: 东风中路 | J16: 5-10年 | K16: 本科 | L16: 15-25K | M16: 团建聚餐|带薪年假|节日福利|定期体检|年终奖|通讯补贴|绩效奖金|股票期权|意外险|交通补助|生日福利|零食下午茶|餐补|五险一金
A17: 14 | B17: 销售经理 | C17: 电科金仓 | D17: {=_xlfn.IFS(J17="经验不限","初级",J17="1-3年","初级",J17="3-5年","中级",J17="5-10年","高级",J17="10年以上","资深")} -> 中级 | E17: {=_xlfn.IFS(D17="初级",1,D17="中级",2,D17="高级",3,D17="资深",4,D17="管理",5)} -> 2 | F17: 区域行业 | G17: 深圳 | H17: 福田区 | I17: 石厦 | J17: 3-5年 | K17: 本科 | L17: 20-28K | M17: 交通补助|带薪年假|生日福利|意外险|团建聚餐|节日福利|年终奖|五险一金|餐补|绩效奖金|通讯补贴|定期体检|股票期权|零食下午茶
A18: 15 | B18: 销售经理/总监 | C18: 电科金仓 | D18: 管理 | E18: {=_xlfn.IFS(D18="初级",1,D18="中级",2,D18="高级",3,D18="资深",4,D18="管理",5)} -> 5 | F18: 电力行业 | G18: 北京 | H18: 朝阳区 | I18: 望京 | J18: 3-5年 | K18: 本科 | L18: 15-30K | M18: 绩效奖金|零食下午茶|生日福利|年终奖|带薪年假|节日福利|餐补|股票期权|团建聚餐|五险一金|定期体检|通讯补贴|意外险|交通补助
A19: 16 | B19: 销售总监 | C19: 电科金仓 | D19: 管理 | E19: {=_xlfn.IFS(D19="初级",1,D19="中级",2,D19="高级",3,D19="资深",4,D19="管理",5)} -> 5 | F19: 区域行业 | G19: 上海 | H19: 浦东新区 | I19: 陆家嘴 | J19: 5-10年 | K19: 本科 | L19: 20-40K | M19: 绩效奖金|带薪年假|团建聚餐|节日福利|通讯补贴|交通补助|零食下午茶|意外险|餐补|股票期权|定期体检|五险一金|生日福利|年终奖
A20: 17 | B20: 销售经理 | C20: 电科金仓 | D20: {=_xlfn.IFS(J20="经验不限","初级",J20="1-3年","初级",J20="3-5年","中级",J20="5-10年","高级",J20="10年以上","资深")} -> 中级 | E20: {=_xlfn.IFS(D20="初级",1,D20="中级",2,D20="高级",3,D20="资深",4,D20="管理",5)} -> 2 | F20: 区域行业 | G20: 济南 | H20: 历下区 | I20: 奥体 | J20: 3-5年 | K20: 本科 | L20: 12-20K | M20: 股票期权|绩效奖金|年终奖|交通补助|通讯补贴|团建聚餐|带薪年假|意外险|零食下午茶|定期体检|餐补|生日福利|节日福利|五险一金
A21: 18 | B21: 销售经理/总监 | C21: 电科金仓 | D21: 管理 | E21: {=_xlfn.IFS(D21="初级",1,D21="中级",2,D21="高级",3,D21="资深",4,D21="管理",5)} -> 5 | F21: 国防行业 | G21: 北京 | H21: 朝阳区 | I21: 望京 | J21: 3-5年 | K21: 本科 | L21: 15-30K | M21: 绩效奖金|定期体检|节日福利|生日福利|餐补|年终奖|股票期权|零食下午茶|交通补助|通讯补贴|带薪年假|意外险|团建聚餐|五险一金
A22: 19 | B22: 销售经理/总监 | C22: 电科金仓 | D22: 管理 | E22: {=_xlfn.IFS(D22="初级",1,D22="中级",2,D22="高级",3,D22="资深",4,D22="管理",5)} -> 5 | F22: 石油|数据库|石化 | G22: 上海 | H22: 浦东新区 | I22: 陆家嘴 | J22: 5-10年 | K22: 本科 | L22: 15-30K | M22: 绩效奖金|带薪年假|团建聚餐|节日福利|通讯补贴|交通补助|零食下午茶|意外险|餐补|股票期权|定期体检|五险一金|生日福利|年终奖
A23: 20 | B23: 销售总监 | C23: 电科金仓 | D23: 管理 | E23: {=_xlfn.IFS(D23="初级",1,D23="中级",2,D23="高级",3,D23="资深",4,D23="管理",5)} -> 5 | F23: 兵团|软件|数据库 | G23: 乌鲁木齐 | J23: 5-10年 | K23: 本科 | L23: 20-35K | M23: 节日福利|年终奖|交通补助|意外险|团建聚餐|餐补|通讯补贴|五险一金|股票期权|绩效奖金|零食下午茶|生日福利|定期体检|带薪年假
A24: 21 | B24: 销售经理 | C24: 北京海量数据 | D24: {=_xlfn.IFS(J24="经验不限","初级",J24="1-3年","初级",J24="3-5年","中级",J24="5-10年","高级",J24="10年以上","资深")} -> 中级 | E24: {=_xlfn.IFS(D24="初级",1,D24="中级",2,D24="高级",3,D24="资深",4,D24="管理",5)} -> 2 | F24: 杭州渠道 | G24: 杭州 | H24: 滨江区 | I24: 长河 | J24: 3-5年 | K24: 本科 | L24: 11-20K·24薪 | M24: 带薪年假|员工旅游|健身房|五险一金|补充医疗保险|股票期权|零食下午茶|餐补|定期体检|节日福利
A25: 22 | B25: 高级销售经理 | C25: 北京海量数据 | D25: {=_xlfn.IFS(J25="经验不限","初级",J25="1-3年","初级",J25="3-5年","中级",J25="5-10年","高级",J25="10年以上","资深")} -> 高级 | E25: {=_xlfn.IFS(D25="初级",1,D25="中级",2,D25="高级",3,D25="资深",4,D25="管理",5)} -> 3 | F25: 交通安平医疗国央企教育党政 | G25: 福州 | H25: 鼓楼区 | I25: 东街口 | J25: 5-10年 | K25: 本科 | L25: 11-20K·24薪 | M25: 员工旅游|带薪年假|健身房|定期体检|五险一金|餐补|补充医疗保险|节日福利|零食下午茶|股票期权
A26: 23 | B26: 销售岗 | C26: 北京海量数据 | D26: {=_xlfn.IFS(J26="经验不限","初级",J26="1-3年","初级",J26="3-5年","中级",J26="5-10年","高级",J26="10年以上","资深")} -> 初级 | E26: {=_xlfn.IFS(D26="初级",1,D26="中级",2,D26="高级",3,D26="资深",4,D26="管理",5)} -> 1 | G26: 上海 | H26: 长宁区 | I26: 北新泾 | J26: 1-3年 | K26: 本科 | L26: 10-15K·24薪 | M26: 补充医疗保险|股票期权|节日福利|健身房|零食下午茶|带薪年假|定期体检|五险一金|员工旅游|餐补
A27: 24 | B27: 销售岗 | C27: 北京海量数据 | D27: {=_xlfn.IFS(J27="经验不限","初级",J27="1-3年","初级",J27="3-5年","中级",J27="5-10年","高级",J27="10年以上","资深")} -> 初级 | E27: {=_xlfn.IFS(D27="初级",1,D27="中级",2,D27="高级",3,D27="资深",4,D27="管理",5)} -> 1 | F27: 医疗教育政府大企业 | G27: 武汉 | H27: 江汉区 | I27: 常青 | J27: 经验不限 | K27: 本科 | L27: 12-15K·24薪 | M27: 节日福利|餐补|带薪年假|五险一金|股票期权|定期体检|健身房|补充医疗保险|零食下午茶|员工旅游
A28: 25 | B28: 高级销售经理 | C28: 北京海量数据 | D28: {=_xlfn.IFS(J28="经验不限","初级",J28="1-3年","初级",J28="3-5年","中级",J28="5-10年","高级",J28="10年以上","资深")} -> 高级 | E28: {=_xlfn.IFS(D28="初级",1,D28="中级",2,D28="高级",3,D28="资深",4,D28="管理",5)} -> 3 | F28: 交通行业|航司|空管|机场 | G28: 北京 | H28: 海淀区 | I28: 学院路 | J28: 5-10年 | K28: 本科 | L28: 13-14K·24薪 | M28: 员工旅游|股票期权|定期体检|补充医疗保险|健身房|五险一金|餐补|零食下午茶|节日福利|带薪年假
A29: 26 | B29: 销售经理 | C29: 北京海量数据 | D29: {=_xlfn.IFS(J29="经验不限","初级",J29="1-3年","初级",J29="3-5年","中级",J29="5-10年","高级",J29="10年以上","资深")} -> 中级 | E29: {=_xlfn.IFS(D29="初级",1,D29="中级",2,D29="高级",3,D29="资深",4,D29="管理",5)} -> 2 | F29: 政府/教育/医疗/企业/交通/能源 | G29: 北京 | H29: 海淀区 | I29: 学院路 | J29: 3-5年 | K29: 本科 | L29: 13-25K·24薪 | M29: 定期体检|员工旅游|股票期权|五险一金|零食下午茶|餐补|补充医疗保险|节日福利|健身房|带薪年假
A30: 27 | B30: 销售经理 | C30: 北京海量数据 | D30: {=_xlfn.IFS(J30="经验不限","初级",J30="1-3年","初级",J30="3-5年","中级",J30="5-10年","高级",J30="10年以上","资深")} -> 中级 | E30: {=_xlfn.IFS(D30="初级",1,D30="中级",2,D30="高级",3,D30="资深",4,D30="管理",5)} -> 2 | F30: 软件/信息化服务销售经验|医疗/大健康|定制解决方案|先进制造|B端市场开发经验|面销/陌拜经验|业务开拓能力|收集分析市场信息|客户关系维护|新客户开发|计算机相关学历|商务谈判技巧|市场营销相关学历|较多外勤|企业服务|通信/网络设备|制定销售策略和目标|软件/SaaS|互联网/科技 | G30: 长沙 | H30: 开福区 | I30: 北辰三角洲 | J30: 3-5年 | K30: 本科 | L30: 15-20K·24薪 | M30: 零食下午茶|带薪年假|五险一金|补充医疗保险|餐补|健身房|节日福利|股票期权|员工旅游|定期体检
A31: 28 | B31: 销售经理 | C31: 北京海量数据 | D31: {=_xlfn.IFS(J31="经验不限","初级",J31="1-3年","初级",J31="3-5年","中级",J31="5-10年","高级",J31="10年以上","资深")} -> 中级 | E31: {=_xlfn.IFS(D31="初级",1,D31="中级",2,D31="高级",3,D31="资深",4,D31="管理",5)} -> 2 | F31: 信创软件 | G31: 南京 | H31: 建邺区 | I31: 江东 | J31: 3-5年 | K31: 本科 | L31: 12-24K | M31: 带薪年假|餐补|五险一金|节日福利|股票期权|员工旅游|补充医疗保险|定期体检|健身房|零食下午茶
A32: 29 | B32: 销售经理 | C32: 北京海量数据 | D32: 中级 | E32: {=_xlfn.IFS(D32="初级",1,D32="中级",2,D32="高级",3,D32="资深",4,D32="管理",5)} -> 2 | G32: 兰州 | H32: 城关区 | I32: 东湖 | J32: 3-5年 | K32: 本科 | L32: 15-25K·14薪 | M32: 五险一金|股票期权|带薪年假|餐补|员工旅游|健身房|零食下午茶|节日福利|补充医疗保险|定期体检
A33: 30 | B33: 销售经理 | C33: 北京海量数据 | D33: {=_xlfn.IFS(J33="经验不限","初级",J33="1-3年","初级",J33="3-5年","中级",J33="5-10年","高级",J33="10年以上","资深")} -> 中级 | E33: {=_xlfn.IFS(D33="初级",1,D33="中级",2,D33="高级",3,D33="资深",4,D33="管理",5)} -> 2 | F33: ka-信息化产品 | G33: 珠海 | H33: 香洲区 | I33: 拱北 | J33: 3-5年 | K33: 本科 | L33: 15-25K·24薪 | M33: 带薪年假|补充医疗保险|五险一金|餐补|零食下午茶|股票期权|节日福利|员工旅游|定期体检|健身房
A34: 31 | B34: 销售经理 | C34: 北京海量数据 | D34: {=_xlfn.IFS(J34="经验不限","初级",J34="1-3年","初级",J34="3-5年","中级",J34="5-10年","高级",J34="10年以上","资深")} -> 中级 | E34: {=_xlfn.IFS(D34="初级",1,D34="中级",2,D34="高级",3,D34="资深",4,D34="管理",5)} -> 2 | F34: 航司轨交铁路 | G34: 上海 | H34: 长宁区 | I34: 北新泾 | J34: 3-5年 | K34: 本科 | L34: 15-25K·24薪 | M34: 股票期权|五险一金|零食下午茶|定期体检|餐补|带薪年假|节日福利|健身房|补充医疗保险|员工旅游
A35: 32 | B35: 大客户销售经理/总监 | C35: 北京海量数据 | D35: 管理 | E35: {=_xlfn.IFS(D35="初级",1,D35="中级",2,D35="高级",3,D35="资深",4,D35="管理",5)} -> 5 | F35: 新客户开发|客户关系维护|软件/SaaS|通信/网络设备|B端市场开发经验|软件/信息化服务销售经验|信创|计算机|软件|硬件|IT服务 | G35: 深圳 | H35: 南山区 | I35: 科技园 | J35: 3-5年 | K35: 本科 | L35: 13-26K·24薪 | M35: 员工旅游|补充医疗保险|定期体检|零食下午茶|健身房|五险一金|餐补|带薪年假|股票期权|节日福利
A36: 33 | B36: 高级销售经理 | C36: 北京海量数据 | D36: {=_xlfn.IFS(J36="经验不限","初级",J36="1-3年","初级",J36="3-5年","中级",J36="5-10年","高级",J36="10年以上","资深")} -> 高级 | E36: {=_xlfn.IFS(D36="初级",1,D36="中级",2,D36="高级",3,D36="资深",4,D36="管理",5)} -> 3 | F36: 医疗/公安/交通-软件/信息化服务销售经验|商务谈判技巧|B端市场开发经验|通信/网络设备|软件/SaaS|业务开拓能力|互联网/科技 | G36: 太原 | H36: 小店区 | I36: 北营 | J36: 5-10年 | K36: 本科 | L36: 12-20K·24薪 | M36: 员工旅游|零食下午茶|餐补|定期体检|节日福利|补充医疗保险|带薪年假|股票期权|健身房|五险一金
A37: 34 | B37: 销售岗 | C37: 北京海量数据 | D37: {=_xlfn.IFS(J37="经验不限","初级",J37="1-3年","初级",J37="3-5年","中级",J37="5-10年","高级",J37="10年以上","资深")} -> 初级 | E37: {=_xlfn.IFS(D37="初级",1,D37="中级",2,D37="高级",3,D37="资深",4,D37="管理",5)} -> 1 | F37: 信创赛道 | G37: 北京 | H37: 海淀区 | I37: 学院路 | J37: 1-3年 | K37: 本科 | L37: 10-15K·24薪 | M37: 五险一金|节日福利|定期体检|健身房|带薪年假|员工旅游|补充医疗保险|餐补|股票期权|零食下午茶
A38: 35 | B38: 销售经理 | C38: 北京海量数据 | D38: {=_xlfn.IFS(J38="经验不限","初级",J38="1-3年","初级",J38="3-5年","中级",J38="5-10年","高级",J38="10年以上","资深")} -> 中级 | E38: {=_xlfn.IFS(D38="初级",1,D38="中级",2,D38="高级",3,D38="资深",4,D38="管理",5)} -> 2 | F38: 软件/信息化服务销售经验|文教卫|B端市场开发经验|教育|医疗|医院|党政 | G38: 海口 | H38: 龙华区 | I38: 滨海大道 | J38: 3-5年 | K38: 本科 | L38: 14-25K·24薪 | M38: 五险一金|定期体检|股票期权|餐补|带薪年假|员工旅游|零食下午茶|健身房|节日福利|补充医疗保险
A39: 36 | B39: 高级销售经理 | C39: 北京海量数据 | D39: {=_xlfn.IFS(J39="经验不限","初级",J39="1-3年","初级",J39="3-5年","中级",J39="5-10年","高级",J39="10年以上","资深")} -> 高级 | E39: {=_xlfn.IFS(D39="初级",1,D39="中级",2,D39="高级",3,D39="资深",4,D39="管理",5)} -> 3 | F39: 公检法司/教育/医疗/高校/粤东医疗 | G39: 深圳 | H39: 南山区 | I39: 科技园 | J39: 5-10年 | K39: 本科 | L39: 11-20K·24薪 | M39: 零食下午茶|补充医疗保险|带薪年假|股票期权|定期体检|节日福利|餐补|健身房|五险一金|员工旅游
A40: 37 | B40: 销售岗 | C40: 北京海量数据 | D40: {=_xlfn.IFS(J40="经验不限","初级",J40="1-3年","初级",J40="3-5年","中级",J40="5-10年","高级",J40="10年以上","资深")} -> 初级 | E40: {=_xlfn.IFS(D40="初级",1,D40="中级",2,D40="高级",3,D40="资深",4,D40="管理",5)} -> 1 | F40: 具有线下渠道销售经验|较强的商务谈判能力|较强的渠道拓展能力|硬件/网络设备|较强的沟通协调能力|较强的市场分析能力|软件/SaaS|渠道/机构客户开发|渠道关系维护 | G40: 上海 | H40: 长宁区 | I40: 北新泾 | J40: 1-3年 | K40: 本科 | L40: 11-20K·24薪 | M40: 节日福利|股票期权|定期体检|带薪年假|五险一金|餐补|健身房|补充医疗保险|零食下午茶|员工旅游
...

Sheet Sheet1
D1: 下限 | E1: 上限 | F1: 年终 | G1: 中位数
A2: 初级 | B2: 经验不限 | C2: =D2&"-"&E2&"K" -> 10-11K | D2: 10 | E2: 11 | G2: =(D2+E2)/2 -> 10.5
A3: 中级 | B3: 3-5年 | C3: =D3&"-"&E3&"K" -> 11-22K | D3: 11 | E3: 22 | G3: =(D3+E3)/2 -> 16.5
A4: 中级 | B4: 3-5年 | C4: =D4&"-"&E4&"K" -> 15-20K | D4: 15 | E4: 20 | G4: =(D4+E4)/2 -> 17.5
A5: 中级 | B5: 3-5年 | C5: =D5&"-"&E5&"K" -> 12-24K | D5: 12 | E5: 24 | G5: =(D5+E5)/2 -> 18
A6: 中级 | B6: 3-5年 | C6: =D6&"-"&E6&"K" -> 15-30K | D6: 15 | E6: 30 | G6: =(D6+E6)/2 -> 22.5
A7: 中级 | B7: 3-5年 | C7: =D7&"-"&E7&"K" -> 15-25K | D7: 15 | E7: 25 | G7: =(D7+E7)/2 -> 20
A8: 管理 | B8: 5-10年 | C8: =D8&"-"&E8&"K" -> 15-30K | D8: 15 | E8: 30 | G8: =(D8+E8)/2 -> 22.5
A9: 中级 | B9: 3-5年 | C9: =D9&"-"&E9&"K" -> 15-30K | D9: 15 | E9: 30 | G9: =(D9+E9)/2 -> 22.5
A10: 中级 | B10: 3-5年 | C10: =D10&"-"&E10&"K" -> 15-25K | D10: 15 | E10: 25 | G10: =(D10+E10)/2 -> 20
A11: 管理 | B11: 10年以上 | C11: =D11&"-"&E11&"K" -> 35-65K | D11: 35 | E11: 65 | G11: =(D11+E11)/2 -> 50
A12: 中级 | B12: 3-5年 | C12: =D12&"-"&E12&"K" -> 12-24K | D12: 12 | E12: 24 | G12: =(D12+E12)/2 -> 18
A13: 高级 | B13: 5-10年 | C13: =D13&"-"&E13&"K" -> 15-25K | D13: 15 | E13: 25 | G13: =(D13+E13)/2 -> 20
... A20: 管理 | B20: 5-10年 | C20: =D20&"-"&E20&"K" -> 20-35K | D20: 20 | E20: 35 | G20: =(D20+E20)/2 -> 27.5
A21: 中级 | B21: 3-5年 | C21: =D21&"-"&E21&"K" -> 11-20K | D21: 11 | E21: 20 | F21: 24薪 | G21: =(D21+E21)/2 -> 15.5
A22: 高级 | B22: 5-10年 | C22: =D22&"-"&E22&"K" -> 11-20K | D22: 11 | E22: 20 | F22: 24薪 | G22: =(D22+E22)/2 -> 15.5
A23: 初级 | B23: 1-3年 | C23: =D23&"-"&E23&"K" -> 10-15K | D23: 10 | E23: 15 | F23: 24薪 | G23: =(D23+E23)/2 -> 12.5
A24: 初级 | B24: 经验不限 | C24: =D24&"-"&E24&"K" -> 12-15K | D24: 12 | E24: 15 | F24: 24薪 | G24: =(D24+E24)/2 -> 13.5
A25: 高级 | B25: 5-10年 | C25: =D25&"-"&E25&"K" -> 13-14K | D25: 13 | E25: 14 | F25: 24薪 | G25: =(D25+E25)/2 -> 13.5
A26: 中级 | B26: 3-5年 | C26: =D26&"-"&E26&"K" -> 13-25K | D26: 13 | E26: 25 | F26: 24薪 | G26: =(D26+E26)/2 -> 19
A27: 中级 | B27: 3-5年 | C27: =D27&"-"&E27&"K" -> 15-20K | D27: 15 | E27: 20 | F27: 24薪 | G27: =(D27+E27)/2 -> 17.5
A28: 中级 | B28: 3-5年 | C28: =D28&"-"&E28&"K" -> 12-24K | D28: 12 | E28: 24 | G28: =(D28+E28)/2 -> 18
A29: 中级 | B29: 3-5年 | C29: =D29&"-"&E29&"K" -> 15-25K | D29: 15 | E29: 25 | F29: 14薪 | G29: =(D29+E29)/2 -> 20
A30: 中级 | B30: 3-5年 | C30: =D30&"-"&E30&"K" -> 15-25K | D30: 15 | E30: 25 | F30: 24薪 | G30: =(D30+E30)/2 -> 20
A31: 中级 | B31: 3-5年 | C31: =D31&"-"&E31&"K" -> 15-25K | D31: 15 | E31: 25 | F31: 24薪 | G31: =(D31+E31)/2 -> 20
A32: 管理 | B32: 3-5年 | C32: =D32&"-"&E32&"K" -> 13-26K | D32: 13 | E32: 26 | F32: 24薪 | G32: =(D32+E32)/2 -> 19.5
A33: 高级 | B33: 5-10年 | C33: =D33&"-"&E33&"K" -> 12-20K | D33: 12 | E33: 20 | F33: 24薪 | G33: =(D33+E33)/2 -> 16
A34: 初级 | B34: 1-3年 | C34: =D34&"-"&E34&"K" -> 10-15K | D34: 10 | E34: 15 | F34: 24薪 | G34: =(D34+E34)/2 -> 12.5
A35: 中级 | B35: 3-5年 | C35: =D35&"-"&E35&"K" -> 14-25K | D35: 14 | E35: 25 | F35: 24薪 | G35: =(D35+E35)/2 -> 19.5
A36: 高级 | B36: 5-10年 | C36: =D36&"-"&E36&"K" -> 11-20K | D36: 11 | E36: 20 | F36: 24薪 | G36: =(D36+E36)/2 -> 15.5
A37: 初级 | B37: 1-3年 | C37: =D37&"-"&E37&"K" -> 11-20K | D37: 11 | E37: 20 | F37: 24薪 | G37: =(D37+E37)/2 -> 15.5
A38: 中级 | B38: 3-5年 | C38: =D38&"-"&E38&"K" -> 15-20K | D38: 15 | E38: 20 | F38: 24薪 | G38: =(D38+E38)/2 -> 17.5
A39: 高级 | B39: 5-10年 | C39: =D39&"-"&E39&"K" -> 10-15K | D39: 10 | E39: 15 | F39: 24薪 | G39: =(D39+E39)/2 -> 12.5
A40: 中级 | B40: 3-5年 | C40: =D40&"-"&E40&"K" -> 11-20K | D40: 11 | E40: 20 | F40: 24薪 | G40: =(D40+E40)/2 -> 15.5
A41: 高级 | B41: 5-10年 | C41: =D41&"-"&E41&"K" -> 15-30K | D41: 15 | E41: 30 | G41: =(D41+E41)/2 -> 22.5
A42: 中级 | B42: 3-5年 | C42: =D42&"-"&E42&"K" -> 12-24K | D42: 12 | E42: 24 | G42: =(D42+E42)/2 -> 18
A43: 中级 | B43: 3-5年 | C43: =D43&"-"&E43&"K" -> 12-24K | D43: 12 | E43: 24 | G43: =(D43+E43)/2 -> 18
A44: 中级 | B44: 3-5年 | C44: =D44&"-"&E44&"K" -> 15-25K | D44: 15 | E44: 25 | F44: 24薪 | G44: =(D44+E44)/2 -> 20
A45: 高级 | B45: 5-10年 | C45: =D45&"-"&E45&"K" -> 15-25K | D45: 15 | E45: 25 | F45: 14薪 | G45: =(D45+E45)/2 -> 20
A46: 中级 | B46: 3-5年 | C46: =D46&"-"&E46&"K" -> 13-26K | D46: 13 | E46: 26 | G46: =(D46+E46)/2 -> 19.5
...

Sheet Sheet2
B1: 初级 | F1: 中级 | J1: 高级 | N1: 资深 | R1: 管理
B2: 10 | C2: 11 | D2: =(B2+C2)/2 -> 10.5 | F2: 11 | G2: 22 | H2: 16.5 | J2: 15 | K2: 25 | L2: 20 | N2: 30 | O2: 60 | P2: 45 | R2: 15 | S2: 30 | T2: 22.5
B3: 10 | C3: 15 | D3: =(B3+C3)/2 -> 12.5 | F3: 15 | G3: 20 | H3: 17.5 | J3: 11 | K3: 20 | L3: 15.5 | N3: 35 | O3: 65 | P3: 50 | R3: 35 | S3: 65 | T3: 50
B4: 12 | C4: 15 | D4: =(B4+C4)/2 -> 13.5 | F4: 12 | G4: 24 | H4: 18 | J4: 13 | K4: 14 | L4: 13.5 | N4: 26 | O4: 50 | P4: 38 | R4: 15 | S4: 30 | T4: 22.5
B5: 10 | C5: 15 | D5: =(B5+C5)/2 -> 12.5 | F5: 15 | G5: 30 | H5: 22.5 | J5: 12 | K5: 20 | L5: 16 | N5: 30 | O5: 60 | P5: 45 | R5: 20 | S5: 40 | T5: 30
B6: 11 | C6: 20 | D6: =(B6+C6)/2 -> 15.5 | F6: 15 | G6: 25 | H6: 20 | J6: 11 | K6: 20 | L6: 15.5 | N6: 30 | O6: 60 | P6: 45 | R6: 15 | S6: 30 | T6: 22.5
B7: 12 | C7: 24 | D7: =(B7+C7)/2 -> 18 | F7: 15 | G7: 30 | H7: 22.5 | J7: 10 | K7: 15 | L7: 12.5 | N7: 30 | O7: 60 | P7: 45 | R7: 15 | S7: 30 | T7: 22.5
B8: 11 | C8: 20 | D8: =(B8+C8)/2 -> 15.5 | F8: 15 | G8: 25 | H8: 20 | J8: 15 | K8: 30 | L8: 22.5 | N8: 30 | O8: 60 | P8: 45 | R8: 20 | S8: 35 | T8: 27.5
B9: 15 | C9: 20 | D9: =(B9+C9)/2 -> 17.5 | F9: 12 | G9: 24 | H9: 18 | J9: 15 | K9: 25 | L9: 20 | N9: 30 | O9: 60 | P9: 45 | R9: 13 | S9: 26 | T9: 19.5
B10: 12 | C10: 18 | D10: =(B10+C10)/2 -> 15 | F10: 20 | G10: 28 | H10: 24 | J10: 15 | K10: 25 | L10: 20 | M10: 平均数 | P10: =AVERAGE(P2:P9) -> 44.75 | R10: 15 | S10: 25 | T10: 20
B11: 10 | C11: 15 | D11: =(B11+C11)/2 -> 12.5 | F11: 12 | G11: 20 | H11: 16 | J11: 11 | K11: 20 | L11: 15.5 | M11: 中位数 | P11: =MEDIAN(P2:P9) -> 45 | R11: 15 | S11: 25 | T11: 20
B12: 11 | C12: 18 | D12: =(B12+C12)/2 -> 14.5 | F12: 11 | G12: 20 | H12: 15.5 | J12: 15 | K12: 30 | L12: 22.5 | R12: 15 | S12: 30 | T12: 22.5
B13: 12 | C13: 20 | D13: =(B13+C13)/2 -> 16 | F13: 13 | G13: 25 | H13: 19 | J13: 15 | K13: 25 | L13: 20 | R13: 20 | S13: 40 | T13: 30
B14: 12 | C14: 18 | D14: =(B14+C14)/2 -> 15 | F14: 15 | G14: 20 | H14: 17.5 | J14: 15 | K14: 30 | L14: 22.5 | Q14: 平均数 | T14: =AVERAGE(T2:T13) -> 25.791667
B15: 10 | C15: 15 | D15: =(B15+C15)/2 -> 12.5 | F15: 12 | G15: 24 | H15: 18 | J15: 12 | K15: 20 | L15: 16 | Q15: 中位数 | T15: =MEDIAN(T2:T13) -> 22.5
B16: 12 | C16: 17 | D16: =(B16+C16)/2 -> 14.5 | F16: 15 | G16: 25 | H16: 20 | J16: 12 | K16: 20 | L16: 16
B17: 11 | C17: 20 | D17: =(B17+C17)/2 -> 15.5 | F17: 15 | G17: 25 | H17: 20 | J17: 15 | K17: 25 | L17: 20
B18: 10 | C18: 15 | D18: =(B18+C18)/2 -> 12.5 | F18: 15 | G18: 25 | H18: 20 | J18: 15 | K18: 30 | L18: 22.5
B19: 12 | C19: 16 | D19: =(B19+C19)/2 -> 14 | F19: 14 | G19: 25 | H19: 19.5 | J19: 20 | K19: 30 | L19: 25
B20: 8 | C20: 13 | D20: =(B20+C20)/2 -> 10.5 | F20: 15 | G20: 20 | H20: 17.5 | J20: 11 | K20: 20 | L20: 15.5
B21: 12 | C21: 16 | D21: =(B21+C21)/2 -> 14 | F21: 11 | G21: 20 | H21: 15.5 | J21: 15 | K21: 25 | L21: 20
B22: 12 | C22: 16 | D22: =(B22+C22)/2 -> 14 | F22: 12 | G22: 24 | H22: 18 | J22: 12 | K22: 20 | L22: 16
B23: 10 | C23: 15 | D23: =(B23+C23)/2 -> 12.5 | F23: 12 | G23: 24 | H23: 18 | J23: 20 | K23: 30 | L23: 25
B24: 12 | C24: 16 | D24: =(B24+C24)/2 -> 14 | F24: 15 | G24: 25 | H24: 20 | J24: 15 | K24: 25 | L24: 20
A25: 平均数 | D25: =AVERAGE(D2:D24) -> 14.021739 | F25: 13 | G25: 26 | H25: 19.5 | J25: 15 | K25: 25 | L25: 20
A26: 中位数 | D26: =MEDIAN(D2:D24) -> 14 | F26: 12 | G26: 24 | H26: 18 | J26: 15 | K26: 16 | L26: 15.5
F27: 10 | G27: 15 | H27: 12.5 | J27: 30 | K27: 50 | L27: 40
F28: 14 | G28: 20 | H28: 17 | J28: 30 | K28: 60 | L28: 45
F29: 15 | G29: 16 | H29: 15.5 | J29: 25 | K29: 40 | L29: 32.5
F30: 10 | G30: 15 | H30: 12.5 | J30: 30 | K30: 35 | L30: 32.5
F31: 8 | G31: 13 | H31: 10.5 | J31: 30 | K31: 50 | L31: 40
F32: 15 | G32: 25 | H32: 20 | J32: 40 | K32: 60 | L32: 50
F33: 12 | G33: 24 | H33: 18 | J33: 35 | K33: 65 | L33: 50
F34: 13 | G34: 26 | H34: 19.5 | J34: 20 | K34: 40 | L34: 30
F35: 12 | G35: 24 | H35: 18 | J35: 30 | K35: 60 | L35: 45
F36: 20 | G36: 30 | H36: 25 | J36: 30 | K36: 60 | L36: 45
F37: 11 | G37: 20 | H37: 15.5 | J37: 30 | K37: 60 | L37: 45
F38: 10 | G38: 15 | H38: 12.5 | J38: 30 | K38: 60 | L38: 45
... F40: 11 | G40: 22 | H40: 16.5 | J40: 35 | K40: 65 | L40: 50
F41: 11 | G41: 20 | H41: 15.5 | I41: 平均数 | J41: 30 | K41: 50 | L41: 40
...
